Workbook

Sheet Sales_Data
A1: Order_ID | B1: Order_Date | C1: Region | D1: Division | E1: Product_Category | F1: Product_Name | G1: Salesperson | H1: Units_Sold | I1: Unit_Price_BDT | J1: Revenue_BDT | K1: Customer_Type
A2: 1001 | B2: 2026-03-24 | C2: Dhaka | D2: Dhaka | E2: RMG Supplies | F2: Cotton Fabric Roll | G2: Farzana Akter | H2: 40 | I2: 3695.53 | J2: =H2*I2 -> 147821.2 | K2: Corporate
A3: 1002 | B3: 2026-03-20 | C3: Dhaka | D3: Narayanganj | E3: Retail Electronics | F3: Walton Fridge | G3: Rafiq Islam | H3: 28 | I3: 1132.26 | J3: =H3*I3 -> 31703.28 | K3: Retail
A4: 1003 | B4: 2026-01-25 | C4: Sylhet | D4: Sylhet | E4: FMCG | F4: Pran Juice Carton | G4: Farzana Akter | H4: 119 | I4: 2966.87 | J4: =H4*I4 -> 353057.53 | K4: Retail
A5: 1004 | B5: 2026-01-13 | C5: Rajshahi | D5: Bogura | E5: RMG Supplies | F5: Cotton Fabric Roll | G5: Farzana Akter | H5: 200 | I5: 1716.14 | J5: =H5*I5 -> 343228 | K5: Retail
A6: 1005 | B6: 2026-01-13 | C6: Khulna | D6: Jessore | E6: FMCG | F6: Pran Juice Carton | G6: Rafiq Islam | H6: 191 | I6: 2324.15 | J6: =H6*I6 -> 443912.65 | K6: Retail
A7: 1006 | B7: 2026-03-08 | C7: Sylhet | D7: Sylhet | E7: FMCG | F7: Pran Juice Carton | G7: Farzana Akter | H7: 185 | I7: 394.3 | J7: =H7*I7 -> 72945.5 | K7: Wholesale
A8: 1007 | B8: 2026-02-06 | C8: Dhaka | D8: Dhaka | E8: Mobile Banking | F8: Nagad POS Device | G8: Shahid Ahmed | H8: 121 | I8: 3196.64 | J8: =H8*I8 -> 386793.44 | K8: Wholesale
A9: 1008 | B9: 2026-03-24 | C9: Khulna | D9: Khulna | E9: RMG Supplies | F9: Garment Labels | G9: Nusrat Jahan | H9: 160 | I9: 3193.14 | J9: =H9*I9 -> 510902.4 | K9: Retail
A10: 1009 | B10: 2026-01-08 | C10: Chattogram | D10: Cox's Bazar | E10: Retail Electronics | F10: Walton TV | G10: Farzana Akter | H10: 180 | I10: 1655.2 | J10: =H10*I10 -> 297936 | K10: Retail
A11: 1010 | B11: 2026-02-07 | C11: Khulna | D11: Jessore | E11: RMG Supplies | F11: Cotton Fabric Roll | G11: Farzana Akter | H11: 150 | I11: 4388.02 | J11: =H11*I11 -> 658203 | K11: Corporate
A12: 1011 | B12: 2026-03-18 | C12: Rajshahi | D12: Bogura | E12: Retail Electronics | F12: Walton Fridge | G12: Shahid Ahmed | H12: 40 | I12: 1270.81 | J12: =H12*I12 -> 50832.4 | K12: Wholesale
A13: 1012 | B13: 2026-01-17 | C13: Sylhet | D13: Sylhet | E13: FMCG | F13: Pran Juice Carton | G13: Mitu Rahman | H13: 61 | I13: 4986.76 | J13: =H13*I13 -> 304192.36 | K13: Wholesale
... A181: 1180 | B181: 2026-01-14 | C181: Sylhet | D181: Sylhet | E181: Mobile Banking | F181: Nagad POS Device | G181: Farzana Akter | H181: 82 | I181: 653.15 | J181: =H181*I181 -> 53558.3 | K181: Corporate

Sheet Dynamic_Arrays
A1: 1.UNIQUE — Region column থেকে distinct list, duplicate ছাড়া, spill হয়ে নিচে আসে | L1: FILTER AND condition — * দিয়ে, Dhaka + Corporate দুটোই লাগবে
B2: {=_xlfn.UNIQUE(Sales_Data!C2:C181)} -> Dhaka | L2: {=_xlfn._xlws.FILTER(Sales_Data!A2:K181,(Sales_Data!C2:C181="Dhaka")*(Sales_Data!K2:K181="Corporate"))} -> 1001 | M2: 2026-03-24 | N2: Dhaka | O2: Dhaka | P2: RMG Supplies | Q2: Cotton Fabric Roll | R2: Farzana Akter | S2: 40 | T2: 3695.53 | U2: 147821.2 | V2: Corporate
B3: Sylhet | L3: 1024 | M3: 2026-03-02 | N3: Dhaka | O3: Narayanganj | P3: Retail Electronics | Q3: Walton TV | R3: Jahangir Alam | S3: 110 | T3: 2361.77 | U3: 259794.7 | V3: Corporate
B4: Rajshahi | L4: 1057 | M4: 2026-03-27 | N4: Dhaka | O4: Gazipur | P4: Telecom | Q4: Robi Internet Pack | R4: Mitu Rahman | S4: 198 | T4: 4462.56 | U4: 883586.88 | V4: Corporate
B5: Khulna | L5: 1092 | M5: 2026-03-10 | N5: Dhaka | O5: Dhaka | P5: Telecom | Q5: Robi Internet Pack | R5: Shahid Ahmed | S5: 117 | T5: 665.55 | U5: 77869.35 | V5: Corporate
B6: Chattogram | L6: 1155 | M6: 2026-01-03 | N6: Dhaka | O6: Gazipur | P6: RMG Supplies | Q6: Garment Labels | R6: Mitu Rahman | S6: 61 | T6: 1698.69 | U6: 103620.09 | V6: Corporate
L9: FILTER no-match — Barisal নেই, IFERROR দিয়ে error handle
N10: {=IFERROR(_xlfn._xlws.FILTER(Sales_Data!A2:K181,Sales_Data!C2:C181="Barisal"),"কোনো ডেটা নেই")} -> কোনো ডেটা নেই
A11: UNIQUE — Product Category column থেকে distinct list
C12: {=_xlfn.UNIQUE(Sales_Data!E146:E181)} -> Mobile Banking
C13: FMCG
C14: Retail Electronics
C15: RMG Supplies
C16: Telecom
C19: FILTER single condition — শুধু Dhaka region-এর সব order | M19: SEQUENCE — 1 থেকে 10, automatic serial number | S19: SEQUENCE — 100 থেকে শুরু, 10 করে কমবে → 100,90,80,70,60
A20: {=_xlfn._xlws.FILTER(Sales_Data!A2:K181,Sales_Data!C2:C181="Dhaka")} -> 1001 | B20: 2026-03-24 | C20: Dhaka | D20: Dhaka | E20: RMG Supplies | F20: Cotton Fabric Roll | G20: Farzana Akter | H20: 40 | I20: 3695.53 | J20: 147821.2 | K20: Corporate | N20: {=_xlfn.SEQUENCE(10)} -> 1 | S20: {=_xlfn.SEQUENCE(5,1,100,-10)} -> 100
A21: 1002 | B21: 2026-03-20 | C21: Dhaka | D21: Narayanganj | E21: Retail Electronics | F21: Walton Fridge | G21: Rafiq Islam | H21: 28 | I21: 1132.26 | J21: 31703.28 | K21: Retail | N21: 2 | S21: 90
A22: 1007 | B22: 2026-02-06 | C22: Dhaka | D22: Dhaka | E22: Mobile Banking | F22: Nagad POS Device | G22: Shahid Ahmed | H22: 121 | I22: 3196.64 | J22: 386793.44 | K22: Wholesale | N22: 3 | S22: 80
A23: 1013 | B23: 2026-01-13 | C23: Dhaka | D23: Dhaka | E23: Mobile Banking | F23: bKash Agent Kit | G23: Kamal Hossain | H23: 179 | I23: 2139.69 | J23: 383004.51 | K23: Wholesale | N23: 4 | S23: 70
A24: 1022 | B24: 2026-02-22 | C24: Dhaka | D24: Dhaka | E24: Mobile Banking | F24: bKash Agent Kit | G24: Mitu Rahman | H24: 23 | I24: 2595.07 | J24: 59686.61 | K24: Wholesale | N24: 5 | S24: 60
A25: 1024 | B25: 2026-03-02 | C25: Dhaka | D25: Narayanganj | E25: Retail Electronics | F25: Walton TV | G25: Jahangir Alam | H25: 110 | I25: 2361.77 | J25: 259794.7 | K25: Corporate | N25: 6
A26: 1025 | B26: 2026-01-18 | C26: Dhaka | D26: Dhaka | E26: Retail Electronics | F26: Singer Blender | G26: Mitu Rahman | H26: 32 | I26: 1280.85 | J26: 40987.2 | K26: Wholesale | N26: 7
A27: 1027 | B27: 2026-01-14 | C27: Dhaka | D27: Dhaka | E27: FMCG | F27: ACI Soap Pack | G27: Nusrat Jahan | H27: 197 | I27: 4251.04 | J27: 837454.88 | K27: Wholesale | N27: 8
A28: 1034 | B28: 2026-03-09 | C28: Dhaka | D28: Dhaka | E28: Retail Electronics | F28: Singer Blender | G28: Nusrat Jahan | H28: 23 | I28: 2711.29 | J28: 62359.67 | K28: Retail | N28: 9
A29: 1040 | B29: 2026-01-14 | C29: Dhaka | D29: Narayanganj | E29: Telecom | F29: Banglalink Bundle | G29: Rafiq Islam | H29: 99 | I29: 2933.42 | J29: 290408.58 | K29: Retail | N29: 10
A30: 1041 | B30: 2026-03-04 | C30: Dhaka | D30: Gazipur | E30: RMG Supplies | F30: Cotton Fabric Roll | G30: Mitu Rahman | H30: 58 | I30: 3426.23 | J30: 198721.34 | K30: Wholesale
A31: 1044 | B31: 2026-01-08 | C31: Dhaka | D31: Gazipur | E31: Telecom | F31: Grameenphone SIM | G31: Sumaiya Khan | H31: 94 | I31: 1560.69 | J31: 146704.86 | K31: Retail
A32: 1056 | B32: 2026-01-18 | C32: Dhaka | D32: Dhaka | E32: Retail Electronics | F32: Walton Fridge | G32: Kamal Hossain | H32: 183 | I32: 2613.89 | J32: 478341.87 | K32: Retail
A33: 1057 | B33: 2026-03-27 | C33: Dhaka | D33: Gazipur | E33: Telecom | F33: Robi Internet Pack | G33: Mitu Rahman | H33: 198 | I33: 4462.56 | J33: 883586.88 | K33: Corporate
A34: 1062 | B34: 2026-02-28 | C34: Dhaka | D34: Narayanganj | E34: Retail Electronics | F34: Walton TV | G34: Rafiq Islam | H34: 95 | I34: 1528.13 | J34: 145172.35 | K34: Wholesale
A35: 1082 | B35: 2026-03-18 | C35: Dhaka | D35: Dhaka | E35: RMG Supplies | F35: Cotton Fabric Roll | G35: Mitu Rahman | H35: 50 | I35: 1546.22 | J35: 77311 | K35: Retail
A36: 1084 | B36: 2026-01-02 | C36: Dhaka | D36: Dhaka | E36: FMCG | F36: Pran Juice Carton | G36: Sumaiya Khan | H36: 127 | I36: 2230.32 | J36: 283250.64 | K36: Wholesale
A37: 1088 | B37: 2026-01-08 | C37: Dhaka | D37: Narayanganj | E37: Mobile Banking | F37: bKash Agent Kit | G37: Farzana Akter | H37: 72 | I37: 3319.12 | J37: 238976.64 | K37: Retail
A38: 1092 | B38: 2026-03-10 | C38: Dhaka | D38: Dhaka | E38: Telecom | F38: Robi Internet Pack | G38: Shahid Ahmed | H38: 117 | I38: 665.55 | J38: 77869.35 | K38: Corporate
A39: 1115 | B39: 2026-02-19 | C39: Dhaka | D39: Gazipur | E39: RMG Supplies | F39: Garment Labels | G39: Kamal Hossain | H39: 23 | I39: 2236.56 | J39: 51440.88 | K39: Wholesale
A40: 1118 | B40: 2026-01-20 | C40: Dhaka | D40: Narayanganj | E40: Mobile Banking | F40: Rocket Sim Pack | G40: Sumaiya Khan | H40: 78 | I40: 3889.92 | J40: 303413.76 | K40: Wholesale
A41: 1133 | B41: 2026-01-24 | C41: Dhaka | D41: Dhaka | E41: RMG Supplies | F41: Cotton Fabric Roll | G41: Kamal Hossain | H41: 194 | I41: 2133.75 | J41: 413947.5 | K41: Retail
... A50: 1176 | B50: 2026-03-12 | C50: Dhaka | D50: Dhaka | E50: Retail Electronics | F50: Walton TV | G50: Rafiq Islam | H50: 111 | I50: 313.62 | J50: 34811.82 | K50: Retail
B56: SORT — column 10 (Revenue) অনুযায়ী বড় থেকে ছোট, -1=descending | N56: SORTBY — Salesperson নাম দেখাবে, Revenue অনুযায়ী rank | U56: COMBINE — আগে FILTER (Chattogram), তারপর SORT (Revenue desc), ভেতর থেকে বাইরে execute হয়
A57: {=_xlfn._xlws.SORT(Sales_Data!A2:K181,10,-1)} -> 1057 | B57: 2026-03-27 | C57: Dhaka | D57: Gazipur | E57: Telecom | F57: Robi Internet Pack | G57: Mitu Rahman | H57: 198 | I57: 4462.56 | J57: 883586.88 | K57: Corporate | N57: {=_xlfn.SORTBY(Sales_Data!G2:G181,Sales_Data!J2:J181,-1)} -> Mitu Rahman | U57: {=_xlfn._xlws.SORT(_xlfn._xlws.FILTER(Sales_Data!A2:K181,Sales_Data!C2:C181="Chattogram"),10,-1)} -> 1087 | V57: 2026-02-19 | W57: Chattogram | X57: Cox's Bazar | Y57: Retail Electronics | Z57: Walton TV | AA57: Shahid Ahmed | AB57: 155 | AC57: 4950.65 | AD57: 767350.75 | AE57: Corporate
...
